[2025-10-09T11:31:47.775+0000] {local_task_job_runner.py:120} INFO - ::group::Pre task execution logs
[2025-10-09T11:31:47.826+0000] {taskinstance.py:2076} INFO - Dependencies all met for dep_context=non-requeueable deps ti=<TaskInstance: pipeline_flow.load_ratings manual__2025-10-09T11:31:11.456760+00:00 [queued]>
[2025-10-09T11:31:47.842+0000] {taskinstance.py:2076} INFO - Dependencies all met for dep_context=requeueable deps ti=<TaskInstance: pipeline_flow.load_ratings manual__2025-10-09T11:31:11.456760+00:00 [queued]>
[2025-10-09T11:31:47.844+0000] {taskinstance.py:2306} INFO - Starting attempt 1 of 2
[2025-10-09T11:31:47.864+0000] {taskinstance.py:2330} INFO - Executing <Task(PythonOperator): load_ratings> on 2025-10-09 11:31:11.456760+00:00
[2025-10-09T11:31:47.877+0000] {logging_mixin.py:188} WARNING - /home/***/.local/lib/python3.12/site-packages/***/task/task_runner/standard_task_runner.py:62 DeprecationWarning: This process (pid=629) is multi-threaded, use of fork() may lead to deadlocks in the child.
[2025-10-09T11:31:47.880+0000] {standard_task_runner.py:64} INFO - Started process 633 to run task
[2025-10-09T11:31:47.877+0000] {standard_task_runner.py:90} INFO - Running: ['***', 'tasks', 'run', 'pipeline_flow', 'load_ratings', 'manual__2025-10-09T11:31:11.456760+00:00', '--job-id', '20', '--raw', '--subdir', 'DAGS_FOLDER/pipeline_dag.py', '--cfg-path', '/tmp/tmpctyqi9v5']
[2025-10-09T11:31:47.883+0000] {standard_task_runner.py:91} INFO - Job 20: Subtask load_ratings
[2025-10-09T11:31:48.014+0000] {task_command.py:426} INFO - Running <TaskInstance: pipeline_flow.load_ratings manual__2025-10-09T11:31:11.456760+00:00 [running]> on host 321597a50810
[2025-10-09T11:31:48.174+0000] {taskinstance.py:2648} INFO - Exporting env vars: AIRFLOW_CTX_DAG_EMAIL='oluwaseyiogundimu10@gmail.com' AIRFLOW_CTX_DAG_OWNER='seyi' AIRFLOW_CTX_DAG_ID='pipeline_flow' AIRFLOW_CTX_TASK_ID='load_ratings' AIRFLOW_CTX_EXECUTION_DATE='2025-10-09T11:31:11.456760+00:00' AIRFLOW_CTX_TRY_NUMBER='1' AIRFLOW_CTX_DAG_RUN_ID='manual__2025-10-09T11:31:11.456760+00:00'
[2025-10-09T11:31:48.176+0000] {taskinstance.py:430} INFO - ::endgroup::
[2025-10-09T11:31:48.205+0000] {transform.py:90} INFO - Starting transformations for ratings..
[2025-10-09T11:31:48.209+0000] {logging_mixin.py:188} WARNING - /home/***/.local/lib/python3.12/site-packages/***/utils/context.py:320 AirflowContextDeprecationWarning: Accessing 'execution_date' from the template is deprecated and will be removed in a future version. Please use 'data_interval_start' or 'logical_date' instead.
[2025-10-09T11:31:48.210+0000] {read_write_buckets.py:26} INFO - Reading ratings.csv from movie-pipeline-bronze bucket.
[2025-10-09T11:31:55.391+0000] {read_write_buckets.py:34} INFO - Successfully read ratings.csv into DataFrame. Shape: (100000, 4)
[2025-10-09T11:31:55.420+0000] {taskinstance.py:441} INFO - ::group::Post task execution logs
[2025-10-09T11:31:55.421+0000] {taskinstance.py:2905} ERROR - Task failed with exception
Traceback (most recent call last):
  File "/home/airflow/.local/lib/python3.12/site-packages/airflow/models/taskinstance.py", line 465, in _execute_task
    result = _execute_callable(context=context, **execute_callable_kwargs)
             ^^^^^^^^^^^^^^^^^^^^^^^^^^^^^^^^^^^^^^^^^^^^^^^^^^^^^^^^^^^^^
  File "/home/airflow/.local/lib/python3.12/site-packages/airflow/models/taskinstance.py", line 432, in _execute_callable
    return execute_callable(context=context, **execute_callable_kwargs)
           ^^^^^^^^^^^^^^^^^^^^^^^^^^^^^^^^^^^^^^^^^^^^^^^^^^^^^^^^^^^^
  File "/home/airflow/.local/lib/python3.12/site-packages/airflow/models/baseoperator.py", line 401, in wrapper
    return func(self, *args, **kwargs)
           ^^^^^^^^^^^^^^^^^^^^^^^^^^^
  File "/home/airflow/.local/lib/python3.12/site-packages/airflow/operators/python.py", line 235, in execute
    return_value = self.execute_callable()
                   ^^^^^^^^^^^^^^^^^^^^^^^
  File "/home/airflow/.local/lib/python3.12/site-packages/airflow/operators/python.py", line 252, in execute_callable
    return self.python_callable(*self.op_args, **self.op_kwargs)
           ^^^^^^^^^^^^^^^^^^^^^^^^^^^^^^^^^^^^^^^^^^^^^^^^^^^^^
  File "/opt/airflow/dags/../pipeline/b_silver/transform.py", line 115, in prepare_ratings_df
    if exec_date <= pipeline_start:
       ^^^^^^^^^^^^^^^^^^^^^^^^^^^
TypeError: can't compare offset-naive and offset-aware datetimes
[2025-10-09T11:31:55.450+0000] {taskinstance.py:1206} INFO - Marking task as UP_FOR_RETRY. dag_id=pipeline_flow, task_id=load_ratings, run_id=manual__2025-10-09T11:31:11.456760+00:00, execution_date=20251009T113111, start_date=20251009T113147, end_date=20251009T113155
[2025-10-09T11:31:55.471+0000] {logging_mixin.py:188} WARNING - /home/***/.local/lib/python3.12/site-packages/***/utils/email.py:154 RemovedInAirflow3Warning: Fetching SMTP credentials from configuration variables will be deprecated in a future release. Please set credentials using a connection instead.
[2025-10-09T11:31:55.472+0000] {configuration.py:1053} WARNING - section/key [smtp/smtp_user] not found in config
[2025-10-09T11:31:55.472+0000] {email.py:271} INFO - Email alerting: attempt 1
[2025-10-09T11:31:55.484+0000] {configuration.py:1053} WARNING - section/key [smtp/smtp_user] not found in config
[2025-10-09T11:31:55.485+0000] {email.py:271} INFO - Email alerting: attempt 1
[2025-10-09T11:31:55.487+0000] {taskinstance.py:879} ERROR - Failed to send email to: oluwaseyiogundimu10@gmail.com
Traceback (most recent call last):
  File "/home/airflow/.local/lib/python3.12/site-packages/airflow/models/taskinstance.py", line 2479, in _run_raw_task
    self._execute_task_with_callbacks(context, test_mode, session=session)
  File "/home/airflow/.local/lib/python3.12/site-packages/airflow/models/taskinstance.py", line 2676, in _execute_task_with_callbacks
    result = self._execute_task(context, task_orig)
             ^^^^^^^^^^^^^^^^^^^^^^^^^^^^^^^^^^^^^^
  File "/home/airflow/.local/lib/python3.12/site-packages/airflow/models/taskinstance.py", line 2701, in _execute_task
    return _execute_task(self, context, task_orig)
           ^^^^^^^^^^^^^^^^^^^^^^^^^^^^^^^^^^^^^^^
  File "/home/airflow/.local/lib/python3.12/site-packages/airflow/models/taskinstance.py", line 465, in _execute_task
    result = _execute_callable(context=context, **execute_callable_kwargs)
             ^^^^^^^^^^^^^^^^^^^^^^^^^^^^^^^^^^^^^^^^^^^^^^^^^^^^^^^^^^^^^
  File "/home/airflow/.local/lib/python3.12/site-packages/airflow/models/taskinstance.py", line 432, in _execute_callable
    return execute_callable(context=context, **execute_callable_kwargs)
           ^^^^^^^^^^^^^^^^^^^^^^^^^^^^^^^^^^^^^^^^^^^^^^^^^^^^^^^^^^^^
  File "/home/airflow/.local/lib/python3.12/site-packages/airflow/models/baseoperator.py", line 401, in wrapper
    return func(self, *args, **kwargs)
           ^^^^^^^^^^^^^^^^^^^^^^^^^^^
  File "/home/airflow/.local/lib/python3.12/site-packages/airflow/operators/python.py", line 235, in execute
    return_value = self.execute_callable()
                   ^^^^^^^^^^^^^^^^^^^^^^^
  File "/home/airflow/.local/lib/python3.12/site-packages/airflow/operators/python.py", line 252, in execute_callable
    return self.python_callable(*self.op_args, **self.op_kwargs)
           ^^^^^^^^^^^^^^^^^^^^^^^^^^^^^^^^^^^^^^^^^^^^^^^^^^^^^
  File "/opt/airflow/dags/../pipeline/b_silver/transform.py", line 115, in prepare_ratings_df
    if exec_date <= pipeline_start:
       ^^^^^^^^^^^^^^^^^^^^^^^^^^^
TypeError: can't compare offset-naive and offset-aware datetimes

During handling of the above exception, another exception occurred:

Traceback (most recent call last):
  File "/home/airflow/.local/lib/python3.12/site-packages/airflow/models/taskinstance.py", line 1063, in _email_alert
    send_email(task.email, subject, html_content)
  File "/home/airflow/.local/lib/python3.12/site-packages/airflow/utils/email.py", line 80, in send_email
    return backend(
           ^^^^^^^^
  File "/home/airflow/.local/lib/python3.12/site-packages/airflow/utils/email.py", line 154, in send_email_smtp
    send_mime_email(e_from=mail_from, e_to=recipients, mime_msg=msg, conn_id=conn_id, dryrun=dryrun)
  File "/home/airflow/.local/lib/python3.12/site-packages/airflow/utils/email.py", line 273, in send_mime_email
    smtp_conn = _get_smtp_connection(smtp_host, smtp_port, smtp_timeout, smtp_ssl)
                ^^^^^^^^^^^^^^^^^^^^^^^^^^^^^^^^^^^^^^^^^^^^^^^^^^^^^^^^^^^^^^^^^^
  File "/home/airflow/.local/lib/python3.12/site-packages/airflow/utils/email.py", line 317, in _get_smtp_connection
    return smtplib.SMTP(host=host, port=port, timeout=timeout)
           ^^^^^^^^^^^^^^^^^^^^^^^^^^^^^^^^^^^^^^^^^^^^^^^^^^^
  File "/usr/local/lib/python3.12/smtplib.py", line 255, in __init__
    (code, msg) = self.connect(host, port)
                  ^^^^^^^^^^^^^^^^^^^^^^^^
  File "/usr/local/lib/python3.12/smtplib.py", line 341, in connect
    self.sock = self._get_socket(host, port, self.timeout)
                ^^^^^^^^^^^^^^^^^^^^^^^^^^^^^^^^^^^^^^^^^^
  File "/usr/local/lib/python3.12/smtplib.py", line 312, in _get_socket
    return socket.create_connection((host, port), timeout,
           ^^^^^^^^^^^^^^^^^^^^^^^^^^^^^^^^^^^^^^^^^^^^^^^
  File "/usr/local/lib/python3.12/socket.py", line 853, in create_connection
    raise exceptions[0]
  File "/usr/local/lib/python3.12/socket.py", line 838, in create_connection
    sock.connect(sa)
OSError: [Errno 99] Cannot assign requested address

During handling of the above exception, another exception occurred:

Traceback (most recent call last):
  File "/home/airflow/.local/lib/python3.12/site-packages/airflow/models/taskinstance.py", line 877, in _handle_failure
    task_instance.email_alert(error, failure_context["task"])
  File "/home/airflow/.local/lib/python3.12/site-packages/airflow/models/taskinstance.py", line 3163, in email_alert
    _email_alert(task_instance=self, exception=exception, task=task)
  File "/home/airflow/.local/lib/python3.12/site-packages/airflow/models/taskinstance.py", line 1065, in _email_alert
    send_email(task.email, subject, html_content_err)
  File "/home/airflow/.local/lib/python3.12/site-packages/airflow/utils/email.py", line 80, in send_email
    return backend(
           ^^^^^^^^
  File "/home/airflow/.local/lib/python3.12/site-packages/airflow/utils/email.py", line 154, in send_email_smtp
    send_mime_email(e_from=mail_from, e_to=recipients, mime_msg=msg, conn_id=conn_id, dryrun=dryrun)
  File "/home/airflow/.local/lib/python3.12/site-packages/airflow/utils/email.py", line 273, in send_mime_email
    smtp_conn = _get_smtp_connection(smtp_host, smtp_port, smtp_timeout, smtp_ssl)
                ^^^^^^^^^^^^^^^^^^^^^^^^^^^^^^^^^^^^^^^^^^^^^^^^^^^^^^^^^^^^^^^^^^
  File "/home/airflow/.local/lib/python3.12/site-packages/airflow/utils/email.py", line 317, in _get_smtp_connection
    return smtplib.SMTP(host=host, port=port, timeout=timeout)
           ^^^^^^^^^^^^^^^^^^^^^^^^^^^^^^^^^^^^^^^^^^^^^^^^^^^
  File "/usr/local/lib/python3.12/smtplib.py", line 255, in __init__
    (code, msg) = self.connect(host, port)
                  ^^^^^^^^^^^^^^^^^^^^^^^^
  File "/usr/local/lib/python3.12/smtplib.py", line 341, in connect
    self.sock = self._get_socket(host, port, self.timeout)
                ^^^^^^^^^^^^^^^^^^^^^^^^^^^^^^^^^^^^^^^^^^
  File "/usr/local/lib/python3.12/smtplib.py", line 312, in _get_socket
    return socket.create_connection((host, port), timeout,
           ^^^^^^^^^^^^^^^^^^^^^^^^^^^^^^^^^^^^^^^^^^^^^^^
  File "/usr/local/lib/python3.12/socket.py", line 853, in create_connection
    raise exceptions[0]
  File "/usr/local/lib/python3.12/socket.py", line 838, in create_connection
    sock.connect(sa)
OSError: [Errno 99] Cannot assign requested address
[2025-10-09T11:31:55.524+0000] {standard_task_runner.py:110} ERROR - Failed to execute job 20 for task load_ratings (can't compare offset-naive and offset-aware datetimes; 633)
[2025-10-09T11:31:55.578+0000] {local_task_job_runner.py:243} INFO - Task exited with return code 1
[2025-10-09T11:31:55.617+0000] {taskinstance.py:3503} INFO - 0 downstream tasks scheduled from follow-on schedule check
[2025-10-09T11:31:55.622+0000] {local_task_job_runner.py:222} INFO - ::endgroup::
